Workbook

Sheet Original_Data
A1: store_id | B1: month | C1: region | D1: store_type | E1: marketing_spend | F1: footfall | G1: avg_discount_pct | H1: staff_count | I1: inventory_availability_pct | J1: competitor_distance_km | K1: holiday_flag | L1: customer_rating | M1: monthly_sales | N1: monthly_profit
A2: STR-1001 | B2: 45658 | C2: East | D2: Residential | E2: 70389.11 | F2: 8302 | G2: 0.042 | H2: 17 | I2: 75 | J2: 5.28 | K2: 1 | L2: 3.1 | M2: 658832.62 | N2: 84349.93
A3: STR-1001 | B3: 45689 | C3: East | D3: Residential | E3: 43827.89 | F3: 8487 | G3: 0.168 | H3: 23 | I3: 84.4 | J3: 4.31 | K3: 0 | L3: 2.8 | M3: 634436 | N3: 106130.54
A4: STR-1001 | B4: 45717 | C4: East | D4: Residential | E4: 59921.75 | F4: 9113 | G4: 0.133 | H4: 20 | I4: 88 | J4: 12 | K4: 0 | L4: 3.2 | M4: 678722.06 | N4: 101883.86
A5: STR-1001 | B5: 45748 | C5: East | D5: Residential | E5: 56856.63 | F5: 9431 | G5: 0.142 | H5: 23 | I5: 86.9 | J5: 4.97 | K5: 0 | L5: 3.4 | M5: 658920.3 | N5: 97910.37
A6: STR-1002 | B6: 45658 | C6: East | D6: High Street | E6: 48412.64 | F6: 9545 | G6: 0.231 | H6: 21 | I6: 97.6 | J6: 6.94 | K6: 1 | L6: 4.2 | M6: 741341.44 | N6: 119208.17
A7: STR-1002 | B7: 45689 | C7: East | D7: High Street | E7: 64811.21 | F7: 9792 | G7: 0.112 | H7: 20 | I7: 84.2 | J7: 2.88 | K7: 0 | L7: 4.2 | M7: 761835.34 | N7: 149602.23
A8: STR-1002 | B8: 45717 | C8: East | D8: High Street | E8: 46213.45 | F8: 10616 | G8: 0.122 | H8: 22 | I8: 85.2 | J8: 0.2 | K8: 1 | L8: 4.1 | M8: 806615.54 | N8: 131364.62
A9: STR-1002 | B9: 45748 | C9: East | D9: High Street | E9: 68148.52 | F9: 8567 | G9: 0.127 | H9: 23 | I9: 95.6 | J9: 0.8 | K9: 0 | L9: 3.9 | M9: 850164.26 | N9: 149262.75
A10: STR-1003 | B10: 45658 | C10: North | D10: Airport | E10: 71838.86 | F10: 10979 | G10: 0.215 | H10: 26 | I10: 88.6 | J10: 7.7 | K10: 1 | L10: 3.8 | M10: 930581.7 | N10: 136207.98
A11: STR-1003 | B11: 45689 | C11: North | D11: Airport | E11: 68133.44 | F11: 9459 | G11: 0.22 | H11: 21 | I11: 85 | J11: 1.91 | K11: 0 | L11: 4.2 | M11: 779010.94 | N11: 106328.09
A12: STR-1003 | B12: 45717 | C12: North | D12: Airport | E12: 34285.21 | F12: 9172 | G12: 0.213 | H12: 22 | I12: 88.3 | J12: 10.46 | K12: 1 | L12: 3.8 | M12: 723060.76 | N12: 123131.24
A13: STR-1003 | B13: 45748 | C13: North | D13: Airport | E13: 67979.88 | F13: 11230 | G13: 0.002 | H13: 28 | I13: 85.3 | J13: 7.16 | K13: 0 | L13: 3.8 | M13: 910791.94 | N13: 158891.28
... A34: STR-1009 | B34: 45658 | C34: North | D34: Residential | E34: 54597.83 | F34: 9429 | G34: 0.188 | H34: 21 | I34: 83.3 | J34: 11.71 | K34: 0 | L34: 4.2 | M34: 641865.03 | N34: 81342.58
A35: STR-1009 | B35: 45689 | C35: North | D35: Residential | E35: 73771.91 | F35: 11695 | G35: 0.07 | H35: 25 | I35: 84.7 | J35: 0.62 | K35: 0 | M35: 799477.76 | N35: 164974.41
A36: STR-1009 | B36: 45717 | C36: North | D36: Residential | E36: 74413.88 | F36: 9449 | G36: 0.039 | H36: 23 | I36: 92.1 | J36: 2.12 | K36: 0 | L36: 3.5 | M36: 798952.17 | N36: 161499.04
A37: STR-1009 | B37: 45748 | C37: North | D37: Residential | E37: 52483.77 | F37: 10453 | G37: 0.247 | H37: 25 | I37: 99 | J37: 6.31 | K37: 0 | L37: 3.6 | M37: 800979.78 | N37: 149242.27
A38: STR-1010 | B38: 45658 | C38: North | D38: Mall | E38: 75269.87 | F38: 8838 | G38: 0.092 | H38: 21 | I38: 83.1 | J38: 9.56 | K38: 1 | L38: 4.2 | M38: 820593.93 | N38: 115860.06
A39: STR-1010 | B39: 45689 | C39: North | D39: Mall | E39: 61245.41 | F39: 8156 | G39: 0.156 | H39: 19 | I39: 92.9 | J39: 9.05 | K39: 0 | L39: 3.8 | M39: 718330.53 | N39: 93247.9
A40: STR-1010 | B40: 45717 | C40: North | D40: Mall | E40: 93381.26 | F40: 7562 | G40: 0.198 | H40: 19 | I40: 82.9 | J40: 5.05 | K40: 0 | L40: 4 | M40: 736633.4 | N40: 115654.66
A41: STR-1010 | B41: 45748 | C41: North | D41: Mall | E41: 65012.19 | F41: 9598 | G41: 0.085 | H41: 24 | I41: 98.3 | J41: 0.89 | K41: 0 | L41: 3.8 | M41: 828623.85 | N41: 167320.52
A42: STR-1011 | B42: 45658 | C42: East | D42: Mall | E42: 40462.94 | F42: 3660 | G42: 0.218 | H42: 11 | I42: 95.2 | J42: 5.57 | K42: 0 | L42: 4.4 | M42: 592195.85 | N42: 92291.56
A43: STR-1011 | B43: 45689 | C43: East | D43: Mall | E43: 46123.88 | F43: 3227 | G43: 0.143 | H43: 10 | I43: 75.4 | J43: 1.06 | K43: 0 | L43: 4.4 | M43: 532644.46 | N43: 60681.32
A44: STR-1011 | B44: 45717 | C44: East | D44: Mall | E44: 68077.54 | F44: 3360 | G44: 0.128 | H44: 14 | I44: 88.2 | J44: 1.24 | K44: 1 | L44: 4 | M44: 657429.18 | N44: 88919.74
A45: STR-1011 | B45: 45748 | C45: East | D45: Mall | E45: 64882.14 | F45: 3642 | G45: 0.019 | H45: 13 | I45: 87.8 | J45: 4.52 | K45: 0 | L45: 4.2 | M45: 605178 | N45: 106958.74
A46: STR-1012 | B46: 45658 | C46: West | D46: Residential | E46: 138855.51 | F46: 5145 | G46: 0.06 | H46: 17 | I46: 88.2 | J46: 9.58 | K46: 0 | L46: 3.2 | M46: 595467.6 | N46: 104276.46
A47: STR-1012 | B47: 45689 | C47: West | D47: Residential | E47: 63630.21 | F47: 4460 | G47: 0.235 | H47: 14 | I47: 98.6 | J47: 5.52 | K47: 0 | L47: 3.5 | M47: 599603.4 | N47: 112685.12
... A72: STR-1018 | B72: 45717 | C72: East | D72: High Street | E72: 60571.82 | F72: 3193 | G72: 0.197 | H72: 7 | I72: 99 | J72: 1.43 | K72: 0 | L72: 3.2 | M72: 605023.87 | N72: 98545.81
A73: STR-1018 | B73: 45748 | C73: East | D73: High Street | E73: 55081.16 | F73: 5485 | G73: 0.036 | H73: 12 | I73: 88 | K73: 0 | L73: 3.5 | M73: 674774.09 | N73: 141917.59
A74: STR-1019 | B74: 45658 | C74: East | D74: Residential | E74: 46201.46 | F74: 5918 | G74: 0.277 | H74: 13 | I74: 78.8 | J74: 4.91 | K74: 0 | L74: 4.5 | M74: 616069.41 | N74: 54453.99
A75: STR-1019 | B75: 45689 | C75: East | D75: Residential | E75: 53762.92 | F75: 6821 | G75: 0.066 | H75: 19 | I75: 94.6 | J75: 7.03 | K75: 0 | L75: 4.4 | M75: 630829.94 | N75: 117090.02
A76: STR-1019 | B76: 45717 | C76: East | D76: Residential | E76: 70144.78 | F76: 6806 | G76: 0.178 | H76: 20 | I76: 93.1 | J76: 0.28 | K76: 1 | L76: 4.3 | M76: 788087.68 | N76: 116803.42
A77: STR-1019 | B77: 45748 | C77: East | D77: Residential | E77: 58749.63 | F77: 8252 | G77: 0.203 | H77: 20 | I77: 85.2 | J77: 3.61 | K77: 0 | L77: 4.5 | M77: 680840.36 | N77: 68007.68
A78: STR-1020 | B78: 45658 | C78: South | D78: High Street | E78: 56973.18 | F78: 6662 | G78: 0.1 | H78: 15 | I78: 77.7 | J78: 7.52 | K78: 1 | L78: 3.2 | M78: 643657.47 | N78: 87022.45
A79: STR-1020 | B79: 45689 | C79: South | D79: High Street | E79: 54872.82 | F79: 5962 | G79: 0.064 | H79: 12 | I79: 85.4 | J79: 2.58 | K79: 0 | L79: 2.9 | M79: 691112.6 | N79: 109212.83
A80: STR-1020 | B80: 45717 | C80: South | D80: High Street | E80: 80562.81 | F80: 7470 | G80: 0.172 | H80: 16 | I80: 83.5 | J80: 2.29 | K80: 0 | L80: 3.3 | M80: 776922.17 | N80: 150701.93
A81: STR-1020 | B81: 45748 | C81: South | D81: High Street | E81: 77999.9 | F81: 5974 | G81: 0.252 | H81: 14 | I81: 81.3 | J81: 2.39 | K81: 0 | L81: 3.2 | M81: 636561.34 | N81: 93861.06
A82: STR-1021 | B82: 45658 | C82: West | D82: Mall | E82: 60881.01 | F82: 5410 | G82: 0.179 | H82: 15 | I82: 83.9 | J82: 5.24 | K82: 0 | L82: 4.6 | M82: 621369.58 | N82: 85493.64
A83: STR-1021 | B83: 45689 | C83: West | D83: Mall | E83: 60628.38 | F83: 4451 | G83: 0.095 | H83: 10 | I83: 89.6 | J83: 3.17 | K83: 0 | L83: 4.6 | M83: 682208.01 | N83: 110318.84
A84: STR-1021 | B84: 45717 | C84: West | D84: Mall | E84: 72731.14 | F84: 4644 | G84: 0.084 | H84: 15 | I84: 87.1 | J84: 2.66 | K84: 0 | L84: 4.6 | M84: 727241.86 | N84: 155810.3
...

Sheet Marketing_Regression
A1: SIMPLE REGRESSION ANALYSIS - MARKETING SPEND VS MONTHLY SALES
A3: SUMMARY OUTPUT
A5: Regression Statistics
A6: Multiple R | B6: 0.40895561
A7: R Square | B7: 0.16724469
A8: Adjusted R Square | B8: 0.16462596
A9: Standard Error | B9: 94846.034
A10: Observations | B10: 320
A12: ANOVA
B13: df | C13: SS | D13: MS | E13: F | F13: Significance F
A14: Regression | B14: 1 | C14: 5.7451371e+11 | D14: 5.7451371e+11 | E14: 63.864873 | F14: 2.4800615e-14
A15: Residual | B15: 318 | C15: 2.8606549e+12 | D15: 8.9957701e+09
A16: Total | B16: 319 | C16: 3.4351686e+12
B18: Coefficients | C18: Standard Error | D18: t Stat | E18: P-value | F18: Lower 95% | G18: Upper 95% | H18: Lower 95.0% | I18: Upper 95.0%
A19: Intercept | B19: 560777.35 | C19: 15906.906 | D19: 35.253703 | E19: 6.9528769e-112 | F19: 529481.27 | G19: 592073.42 | H19: 529481.27 | I19: 592073.42
A20: marketing_spend | B20: 2.1295753 | C20: 0.26647838 | D20: 7.9915501 | E20: 2.4800615e-14 | F20: 1.6052919 | G20: 2.6538587 | H20: 1.6052919 | I20: 2.6538587
A22: Key Findings: • Marketing Spend has a positive relationship with Monthly Sales. • Coefficient = 2.13, indicating higher marketing investment is associated with higher sales. • P-value is below 0.05, showing statistical significance. • R² = 0.167, meaning Marketing Spend explains approximately 16.7% of sales variation. • Marketing Spend is useful but not sufficient alone to explain store sales performance.

Sheet Simple_Regression
A1: SIMPLE REGRESSION ANALYSIS - FOOTFALL VS MONTHLY SALES
A3: SUMMARY OUTPUT
A5: Regression Statistics
A6: Multiple R | B6: 0.85807071
A7: R Square | B7: 0.73628534
A8: Adjusted R Square | B8: 0.73545605
A9: Standard Error | B9: 53373.736
A10: Observations | B10: 320
A12: ANOVA
B13: df | C13: SS | D13: MS | E13: F | F13: Significance F
A14: Regression | B14: 1 | C14: 2.5292643e+12 | D14: 2.5292643e+12 | E14: 887.84878 | F14: 4.7503615e-94
A15: Residual | B15: 318 | C15: 9.0590432e+11 | D15: 2.8487557e+09
A16: Total | B16: 319 | C16: 3.4351686e+12
B18: Coefficients | C18: Standard Error | D18: t Stat | E18: P-value | F18: Lower 95% | G18: Upper 95% | H18: Lower 95.0% | I18: Upper 95.0%
A19: Intercept | B19: 446410.58 | C19: 8407.7383 | D19: 53.095205 | E19: 4.0862696e-160 | F19: 429868.76 | G19: 462952.4 | H19: 429868.76 | I19: 462952.4
A20: footfall | B20: 35.678031 | C20: 1.1973783 | D20: 29.796791 | E20: 4.7503615e-94 | F20: 33.322247 | G20: 38.033815 | H20: 33.322247 | I20: 38.033815
A22: Key Findings: • Footfall is strongly associated with Monthly Sales. • Coefficient = 35.68 indicates each additional customer visit increases expected sales. • P-value is effectively zero, showing strong statistical significance. • R² = 0.736, meaning Footfall explains approximately 73.6% of sales variation. • Footfall is a stronger predictor than Marketing Spend.

Sheet Cleaned_Data
A1: store_id | B1: month | C1: region | D1: store_type | E1: marketing_spend | F1: footfall | G1: avg_discount_pct | H1: staff_count | I1: inventory_availability_pct | J1: competitor_distance_km | K1: holiday_flag | L1: customer_rating | M1: monthly_sales | N1: monthly_profit | O1: Region_North | P1: Region_South | Q1: Region_East
A2: STR-1001 | B2: 45658 | C2: East | D2: Residential | E2: 70389.11 | F2: 8302 | G2: 0.042 | H2: 17 | I2: 75 | J2: 5.28 | K2: 1 | L2: 3.1 | M2: 658832.62 | N2: 84349.93 | O2: 0 | P2: 0 | Q2: 1
A3: STR-1001 | B3: 45689 | C3: East | D3: Residential | E3: 43827.89 | F3: 8487 | G3: 0.168 | H3: 23 | I3: 84.4 | J3: 4.31 | K3: 0 | L3: 2.8 | M3: 634436 | N3: 106130.54 | O3: 0 | P3: 0 | Q3: 1
A4: STR-1001 | B4: 45717 | C4: East | D4: Residential | E4: 59921.75 | F4: 9113 | G4: 0.133 | H4: 20 | I4: 88 | J4: 12 | K4: 0 | L4: 3.2 | M4: 678722.06 | N4: 101883.86 | O4: 0 | P4: 0 | Q4: 1
A5: STR-1001 | B5: 45748 | C5: East | D5: Residential | E5: 56856.63 | F5: 9431 | G5: 0.142 | H5: 23 | I5: 86.9 | J5: 4.97 | K5: 0 | L5: 3.4 | M5: 658920.3 | N5: 97910.37 | O5: 0 | P5: 0 | Q5: 1
A6: STR-1002 | B6: 45658 | C6: East | D6: High Street | E6: 48412.64 | F6: 9545 | G6: 0.231 | H6: 21 | I6: 97.6 | J6: 6.94 | K6: 1 | L6: 4.2 | M6: 741341.44 | N6: 119208.17 | O6: 0 | P6: 0 | Q6: 1
A7: STR-1002 | B7: 45689 | C7: East | D7: High Street | E7: 64811.21 | F7: 9792 | G7: 0.112 | H7: 20 | I7: 84.2 | J7: 2.88 | K7: 0 | L7: 4.2 | M7: 761835.34 | N7: 149602.23 | O7: 0 | P7: 0 | Q7: 1
A8: STR-1002 | B8: 45717 | C8: East | D8: High Street | E8: 46213.45 | F8: 10616 | G8: 0.122 | H8: 22 | I8: 85.2 | J8: 0.2 | K8: 1 | L8: 4.1 | M8: 806615.54 | N8: 131364.62 | O8: 0 | P8: 0 | Q8: 1
A9: STR-1002 | B9: 45748 | C9: East | D9: High Street | E9: 68148.52 | F9: 8567 | G9: 0.127 | H9: 23 | I9: 95.6 | J9: 0.8 | K9: 0 | L9: 3.9 | M9: 850164.26 | N9: 149262.75 | O9: 0 | P9: 0 | Q9: 1
A10: STR-1003 | B10: 45658 | C10: North | D10: Airport | E10: 71838.86 | F10: 10979 | G10: 0.215 | H10: 26 | I10: 88.6 | J10: 7.7 | K10: 1 | L10: 3.8 | M10: 930581.7 | N10: 136207.98 | O10: 1 | P10: 0 | Q10: 0
A11: STR-1003 | B11: 45689 | C11: North | D11: Airport | E11: 68133.44 | F11: 9459 | G11: 0.22 | H11: 21 | I11: 85 | J11: 1.91 | K11: 0 | L11: 4.2 | M11: 779010.94 | N11: 106328.09 | O11: 1 | P11: 0 | Q11: 0
A12: STR-1003 | B12: 45717 | C12: North | D12: Airport | E12: 34285.21 | F12: 9172 | G12: 0.213 | H12: 22 | I12: 88.3 | J12: 10.46 | K12: 1 | L12: 3.8 | M12: 723060.76 | N12: 123131.24 | O12: 1 | P12: 0 | Q12: 0
A13: STR-1003 | B13: 45748 | C13: North | D13: Airport | E13: 67979.88 | F13: 11230 | G13: 0.002 | H13: 28 | I13: 85.3 | J13: 7.16 | K13: 0 | L13: 3.8 | M13: 910791.94 | N13: 158891.28 | O13: 1 | P13: 0 | Q13: 0
... A321: STR-1080 | B321: 45748 | C321: East | D321: Residential | E321: 40553.11 | F321: 5317 | G321: 0.165 | H321: 17 | I321: 84.3 | J321: 11.82 | K321: 0 | L321: 4.1 | M321: 559660.84 | N321: 71443.61 | O321: 0 | P321: 0 | Q321: 1
J322: =COUNTBLANK(J2:J321) -> 0 | K322: =COUNTBLANK(K2:K321) -> 0 | L322: =COUNTBLANK(L2:L321) -> 0

Sheet Dummy_Variables
A1: REGION DUMMY VARIABLE CREATION
A3: region | B3: Region_North | C3: Region_South | D3: Region_East
A4: East | B4: =IF($A4="North",1,0) -> 0 | C4: =IF($A4="South",1,0) -> 0 | D4: =IF($A4="East",1,0) -> 1
A5: East | B5: =IF($A5="North",1,0) -> 0 | C5: =IF($A5="South",1,0) -> 0 | D5: =IF($A5="East",1,0) -> 1
A6: East | B6: =IF($A6="North",1,0) -> 0 | C6: =IF($A6="South",1,0) -> 0 | D6: =IF($A6="East",1,0) -> 1
A7: East | B7: =IF($A7="North",1,0) -> 0 | C7: =IF($A7="South",1,0) -> 0 | D7: =IF($A7="East",1,0) -> 1
A8: East | B8: =IF($A8="North",1,0) -> 0 | C8: =IF($A8="South",1,0) -> 0 | D8: =IF($A8="East",1,0) -> 1
A9: East | B9: =IF($A9="North",1,0) -> 0 | C9: =IF($A9="South",1,0) -> 0 | D9: =IF($A9="East",1,0) -> 1 | F9: Reference Category: West Dummy Variables Created: • Region_North • Region_South • Region_East When all dummy variables = 0, the store belongs to the West region. This approach avoids the dummy variable trap.
A10: East | B10: =IF($A10="North",1,0) -> 0 | C10: =IF($A10="South",1,0) -> 0 | D10: =IF($A10="East",1,0) -> 1
A11: East | B11: =IF($A11="North",1,0) -> 0 | C11: =IF($A11="South",1,0) -> 0 | D11: =IF($A11="East",1,0) -> 1
A12: North | B12: =IF($A12="North",1,0) -> 1 | C12: =IF($A12="South",1,0) -> 0 | D12: =IF($A12="East",1,0) -> 0
A13: North | B13: =IF($A13="North",1,0) -> 1 | C13: =IF($A13="South",1,0) -> 0 | D13: =IF($A13="East",1,0) -> 0
A14: North | B14: =IF($A14="North",1,0) -> 1 | C14: =IF($A14="South",1,0) -> 0 | D14: =IF($A14="East",1,0) -> 0
A15: North | B15: =IF($A15="North",1,0) -> 1 | C15: =IF($A15="South",1,0) -> 0 | D15: =IF($A15="East",1,0) -> 0
A16: East | B16: =IF($A16="North",1,0) -> 0 | C16: =IF($A16="South",1,0) -> 0 | D16: =IF($A16="East",1,0) -> 1
A17: East | B17: =IF($A17="North",1,0) -> 0 | C17: =IF($A17="South",1,0) -> 0 | D17: =IF($A17="East",1,0) -> 1
A18: East | B18: =IF($A18="North",1,0) -> 0 | C18: =IF($A18="South",1,0) -> 0 | D18: =IF($A18="East",1,0) -> 1
A19: East | B19: =IF($A19="North",1,0) -> 0 | C19: =IF($A19="South",1,0) -> 0 | D19: =IF($A19="East",1,0) -> 1
A20: South | B20: =IF($A20="North",1,0) -> 0 | C20: =IF($A20="South",1,0) -> 1 | D20: =IF($A20="East",1,0) -> 0
A21: South | B21: =IF($A21="North",1,0) -> 0 | C21: =IF($A21="South",1,0) -> 1 | D21: =IF($A21="East",1,0) -> 0
... A323: East | B323: =IF($A323="North",1,0) -> 0 | C323: =IF($A323="South",1,0) -> 0 | D323: =IF($A323="East",1,0) -> 1

Sheet Multiple_Regression
A1: MULTIPLE REGRESSION ANALYSIS - MONTHLY SALES MODEL
A3: SUMMARY OUTPUT
A5: Regression Statistics
A6: Multiple R | B6: 0.90241558
A7: R Square | B7: 0.81435389
A8: Adjusted R Square | B8: 0.81018875
A9: Standard Error | B9: 45210.537
A10: Observations | B10: 320
A12: ANOVA
B13: df | C13: SS | D13: MS | E13: F | F13: Significance F
A14: Regression | B14: 7 | C14: 2.7974429e+12 | D14: 3.996347e+11 | E14: 195.5167 | F14: 4.6445309e-110
A15: Residual | B15: 312 | C15: 6.377257e+11 | D15: 2.0439926e+09
A16: Total | B16: 319 | C16: 3.4351686e+12
B18: Coefficients | C18: Standard Error | D18: t Stat | E18: P-value | F18: Lower 95% | G18: Upper 95% | H18: Lower 95.0% | I18: Upper 95.0%
A19: Intercept | B19: 98015.505 | C19: 49240.19 | D19: 1.990559 | E19: 0.047401555 | F19: 1130.6797 | G19: 194900.33 | H19: 1130.6797 | I19: 194900.33
A20: marketing_spend | B20: 1.2022734 | C20: 0.13108107 | D20: 9.1719835 | E20: 6.4895961e-18 | F20: 0.94435873 | G20: 1.460188 | H20: 0.94435873 | I20: 1.460188
A21: footfall | B21: 33.984257 | C21: 1.0501163 | D21: 32.362375 | E21: 1.0011259e-101 | F21: 31.918051 | G21: 36.050462 | H21: 31.918051 | I21: 36.050462
A22: inventory_availability_pct | B22: 2886.7347 | C22: 475.77927 | D22: 6.0673822 | E22: 3.7620281e-09 | F22: 1950.5931 | G22: 3822.8763 | H22: 1950.5931 | I22: 3822.8763
A23: customer_rating | B23: 11024.991 | C23: 4944.7476 | D23: 2.2296366 | E23: 0.026483017 | F23: 1295.7224 | G23: 20754.259 | H23: 1295.7224 | I23: 20754.259
A24: Region_North | B24: -8375.7106 | C24: 7393.5749 | D24: -1.1328364 | E24: 0.25815277 | F24: -22923.283 | G24: 6171.8615 | H24: -22923.283 | I24: 6171.8615
A25: Region_South | B25: 4929.5867 | C25: 7513.8352 | D25: 0.65606798 | E25: 0.51226391 | F25: -9854.6091 | G25: 19713.783 | H25: -9854.6091 | I25: 19713.783
A26: Region_East | B26: -17042.833 | C26: 6518.0764 | D26: -2.6147029 | E26: 0.0093640864 | F26: -29867.778 | G26: -4217.889 | H26: -29867.778 | I26: -4217.889
A29: Key Findings: • Multiple Regression achieved the highest explanatory power (R² = 0.814). • Footfall is the strongest predictor of Monthly Sales. • Marketing Spend and Customer Rating positively influence sales. • Region_East shows significantly lower sales compared to the reference region. • Inventory Availability, Region_North, and Region_South are not statistically significant. • This model was selected as the final business recommendation model.

Sheet Regression_Input_Data
A1: MULTIPLE REGRESSION INPUT DATASET
A3: monthly_sales | B3: marketing_spend | C3: footfall | D3: inventory_availability_pct | E3: customer_rating | F3: Region_North | G3: Region_South | H3: Region_East
A4: 658832.62 | B4: 70389.11 | C4: 8302 | D4: 75 | E4: 3.1 | F4: 0 | G4: 0 | H4: 1
A5: 634436 | B5: 43827.89 | C5: 8487 | D5: 84.4 | E5: 2.8 | F5: 0 | G5: 0 | H5: 1
A6: 678722.06 | B6: 59921.75 | C6: 9113 | D6: 88 | E6: 3.2 | F6: 0 | G6: 0 | H6: 1
A7: 658920.3 | B7: 56856.63 | C7: 9431 | D7: 86.9 | E7: 3.4 | F7: 0 | G7: 0 | H7: 1 | J7: This dataset was prepared for multiple regression analysis. It includes numerical predictors and region dummy variables used in the final model.
A8: 741341.44 | B8: 48412.64 | C8: 9545 | D8: 97.6 | E8: 4.2 | F8: 0 | G8: 0 | H8: 1
A9: 761835.34 | B9: 64811.21 | C9: 9792 | D9: 84.2 | E9: 4.2 | F9: 0 | G9: 0 | H9: 1
A10: 806615.54 | B10: 46213.45 | C10: 10616 | D10: 85.2 | E10: 4.1 | F10: 0 | G10: 0 | H10: 1
A11: 850164.26 | B11: 68148.52 | C11: 8567 | D11: 95.6 | E11: 3.9 | F11: 0 | G11: 0 | H11: 1
A12: 930581.7 | B12: 71838.86 | C12: 10979 | D12: 88.6 | E12: 3.8 | F12: 1 | G12: 0 | H12: 0
A13: 779010.94 | B13: 68133.44 | C13: 9459 | D13: 85 | E13: 4.2 | F13: 1 | G13: 0 | H13: 0
A14: 723060.76 | B14: 34285.21 | C14: 9172 | D14: 88.3 | E14: 3.8 | F14: 1 | G14: 0 | H14: 0
A15: 910791.94 | B15: 67979.88 | C15: 11230 | D15: 85.3 | E15: 3.8 | F15: 1 | G15: 0 | H15: 0
A16: 922168.6 | B16: 71828.26 | C16: 12775 | D16: 81.7 | E16: 4.2 | F16: 0 | G16: 0 | H16: 1
A17: 726606.28 | B17: 55716.82 | C17: 10054 | D17: 84.9 | E17: 4.3 | F17: 0 | G17: 0 | H17: 1
A18: 746501.09 | B18: 59909.51 | C18: 8895 | D18: 88.8 | E18: 4.3 | F18: 0 | G18: 0 | H18: 1
A19: 834017.02 | B19: 75305.71 | C19: 10940 | D19: 76.5 | E19: 4.5 | F19: 0 | G19: 0 | H19: 1
... A323: 559660.84 | B323: 40553.11 | C323: 5317 | D323: 84.3 | E323: 4.1 | F323: 0 | G323: 0 | H323: 1
E324: =COUNTBLANK(E4:E323) -> 0

Sheet Predictions_Residuals
A1: PREDICTED SALES AND RESIDUAL ANALYSIS
F3: TOP 5 POSITIVE RESIDUALS
A4: Actual_Sales | B4: Predicted_Sales | C4: Residual
A5: 685379.08 | B5: =98015.50529 +(1.202273376*Cleaned_Data!E68) +(33.98425653*Cleaned_Data!F68) +(2886.7347*Cleaned_Data!I68) +(11024.99051*Cleaned_Data!L68) +(-8375.710551*Cleaned_Data!O68) +(4929.586703*Cleaned_Data!P68) +(-17042.83335*Cleaned_Data!Q68) -> 841678.34 | C5: =A5-B5 -> -156299.26 | F5: Actual Sales | G5: Predicted Sales | H5: Residual
A6: 595467.6 | B6: =98015.50529 +(1.202273376*Cleaned_Data!E46) +(33.98425653*Cleaned_Data!F46) +(2886.7347*Cleaned_Data!I46) +(11024.99051*Cleaned_Data!L46) +(-8375.710551*Cleaned_Data!O46) +(4929.586703*Cleaned_Data!P46) +(-17042.83335*Cleaned_Data!Q46) -> 729696.76 | C6: =A6-B6 -> -134229.16 | F6: 799046.94 | G6: 706026.96 | H6: 93019.98
A7: 627171.9 | B7: =98015.50529 +(1.202273376*Cleaned_Data!E91) +(33.98425653*Cleaned_Data!F91) +(2886.7347*Cleaned_Data!I91) +(11024.99051*Cleaned_Data!L91) +(-8375.710551*Cleaned_Data!O91) +(4929.586703*Cleaned_Data!P91) +(-17042.83335*Cleaned_Data!Q91) -> 757388.58 | C7: =A7-B7 -> -130216.68 | F7: 813316.71 | G7: 718839.53 | H7: 94477.18
A8: 641865.03 | B8: =98015.50529 +(1.202273376*Cleaned_Data!E34) +(33.98425653*Cleaned_Data!F34) +(2886.7347*Cleaned_Data!I34) +(11024.99051*Cleaned_Data!L34) +(-8375.710551*Cleaned_Data!O34) +(4929.586703*Cleaned_Data!P34) +(-17042.83335*Cleaned_Data!Q34) -> 762488.83 | C8: =A8-B8 -> -120623.8 | F8: 787715.51 | G8: 687127.02 | H8: 100588.5
A9: 538376 | B9: =98015.50529 +(1.202273376*Cleaned_Data!E307) +(33.98425653*Cleaned_Data!F307) +(2886.7347*Cleaned_Data!I307) +(11024.99051*Cleaned_Data!L307) +(-8375.710551*Cleaned_Data!O307) +(4929.586703*Cleaned_Data!P307) +(-17042.83335*Cleaned_Data!Q307) -> 648422.32 | C9: =A9-B9 -> -110046.32 | F9: 625514.04 | G9: 522797.21 | H9: 102716.8
A10: 415721.82 | B10: =98015.50529 +(1.202273376*Cleaned_Data!E22) +(33.98425653*Cleaned_Data!F22) +(2886.7347*Cleaned_Data!I22) +(11024.99051*Cleaned_Data!L22) +(-8375.710551*Cleaned_Data!O22) +(4929.586703*Cleaned_Data!P22) +(-17042.83335*Cleaned_Data!Q22) -> 521959.97 | C10: =A10-B10 -> -106238.15 | F10: 713611.16 | G10: 585781.3 | H10: 127829.9
A11: 800451.94 | B11: =98015.50529 +(1.202273376*Cleaned_Data!E27) +(33.98425653*Cleaned_Data!F27) +(2886.7347*Cleaned_Data!I27) +(11024.99051*Cleaned_Data!L27) +(-8375.710551*Cleaned_Data!O27) +(4929.586703*Cleaned_Data!P27) +(-17042.83335*Cleaned_Data!Q27) -> 900517.55 | C11: =A11-B11 -> -100065.61
A12: 658920.3 | B12: =98015.50529 +(1.202273376*Cleaned_Data!E5) +(33.98425653*Cleaned_Data!F5) +(2886.7347*Cleaned_Data!I5) +(11024.99051*Cleaned_Data!L5) +(-8375.710551*Cleaned_Data!O5) +(4929.586703*Cleaned_Data!P5) +(-17042.83335*Cleaned_Data!Q5) -> 758177.62 | C12: =A12-B12 -> -99257.321
A13: 463534.25 | B13: =98015.50529 +(1.202273376*Cleaned_Data!E54) +(33.98425653*Cleaned_Data!F54) +(2886.7347*Cleaned_Data!I54) +(11024.99051*Cleaned_Data!L54) +(-8375.710551*Cleaned_Data!O54) +(4929.586703*Cleaned_Data!P54) +(-17042.83335*Cleaned_Data!Q54) -> 559538.16 | C13: =A13-B13 -> -96003.907
A14: 449465.06 | B14: =98015.50529 +(1.202273376*Cleaned_Data!E197) +(33.98425653*Cleaned_Data!F197) +(2886.7347*Cleaned_Data!I197) +(11024.99051*Cleaned_Data!L197) +(-8375.710551*Cleaned_Data!O197) +(4929.586703*Cleaned_Data!P197) +(-17042.83335*Cleaned_Data!Q197) -> 544385.13 | C14: =A14-B14 -> -94920.067 | F14: TOP 5 NEGATIVE RESIDUALS
A15: 633638.03 | B15: =98015.50529 +(1.202273376*Cleaned_Data!E138) +(33.98425653*Cleaned_Data!F138) +(2886.7347*Cleaned_Data!I138) +(11024.99051*Cleaned_Data!L138) +(-8375.710551*Cleaned_Data!O138) +(4929.586703*Cleaned_Data!P138) +(-17042.83335*Cleaned_Data!Q138) -> 725431.78 | C15: =A15-B15 -> -91793.751
A16: 673076.34 | B16: =98015.50529 +(1.202273376*Cleaned_Data!E278) +(33.98425653*Cleaned_Data!F278) +(2886.7347*Cleaned_Data!I278) +(11024.99051*Cleaned_Data!L278) +(-8375.710551*Cleaned_Data!O278) +(4929.586703*Cleaned_Data!P278) +(-17042.83335*Cleaned_Data!Q278) -> 758053.24 | C16: =A16-B16 -> -84976.896 | F16: Actual Sales | G16: Predicted Sales | H16: Residual
A17: 684217.32 | B17: =98015.50529 +(1.202273376*Cleaned_Data!E120) +(33.98425653*Cleaned_Data!F120) +(2886.7347*Cleaned_Data!I120) +(11024.99051*Cleaned_Data!L120) +(-8375.710551*Cleaned_Data!O120) +(4929.586703*Cleaned_Data!P120) +(-17042.83335*Cleaned_Data!Q120) -> 768435.36 | C17: =A17-B17 -> -84218.042 | F17: 685379.08 | G17: 841678.34 | H17: =F17-G17 -> -156299.26
A18: 593637.14 | B18: =98015.50529 +(1.202273376*Cleaned_Data!E171) +(33.98425653*Cleaned_Data!F171) +(2886.7347*Cleaned_Data!I171) +(11024.99051*Cleaned_Data!L171) +(-8375.710551*Cleaned_Data!O171) +(4929.586703*Cleaned_Data!P171) +(-17042.83335*Cleaned_Data!Q171) -> 675812.76 | C18: =A18-B18 -> -82175.621 | F18: 595467.6 | G18: 729696.76 | H18: =F18-G18 -> -134229.16
A19: 678722.06 | B19: =98015.50529 +(1.202273376*Cleaned_Data!E4) +(33.98425653*Cleaned_Data!F4) +(2886.7347*Cleaned_Data!I4) +(11024.99051*Cleaned_Data!L4) +(-8375.710551*Cleaned_Data!O4) +(4929.586703*Cleaned_Data!P4) +(-17042.83335*Cleaned_Data!Q4) -> 752026.15 | C19: =A19-B19 -> -73304.09 | F19: 627171.9 | G19: 757388.58 | H19: =F19-G19 -> -130216.68
A20: 511844.41 | B20: =98015.50529 +(1.202273376*Cleaned_Data!E30) +(33.98425653*Cleaned_Data!F30) +(2886.7347*Cleaned_Data!I30) +(11024.99051*Cleaned_Data!L30) +(-8375.710551*Cleaned_Data!O30) +(4929.586703*Cleaned_Data!P30) +(-17042.83335*Cleaned_Data!Q30) -> 584041 | C20: =A20-B20 -> -72196.591 | F20: 641865.03 | G20: 762488.83 | H20: =F20-G20 -> -120623.8
A21: 427917.38 | B21: =98015.50529 +(1.202273376*Cleaned_Data!E33) +(33.98425653*Cleaned_Data!F33) +(2886.7347*Cleaned_Data!I33) +(11024.99051*Cleaned_Data!L33) +(-8375.710551*Cleaned_Data!O33) +(4929.586703*Cleaned_Data!P33) +(-17042.83335*Cleaned_Data!Q33) -> 497117.14 | C21: =A21-B21 -> -69199.759 | F21: 538376 | G21: 648422.32 | H21: =F21-G21 -> -110046.32
A22: 401582.58 | B22: =98015.50529 +(1.202273376*Cleaned_Data!E301) +(33.98425653*Cleaned_Data!F301) +(2886.7347*Cleaned_Data!I301) +(11024.99051*Cleaned_Data!L301) +(-8375.710551*Cleaned_Data!O301) +(4929.586703*Cleaned_Data!P301) +(-17042.83335*Cleaned_Data!Q301) -> 470056.83 | C22: =A22-B22 -> -68474.249
A23: 721079.35 | B23: =98015.50529 +(1.202273376*Cleaned_Data!E238) +(33.98425653*Cleaned_Data!F238) +(2886.7347*Cleaned_Data!I238) +(11024.99051*Cleaned_Data!L238) +(-8375.710551*Cleaned_Data!O238) +(4929.586703*Cleaned_Data!P238) +(-17042.83335*Cleaned_Data!Q238) -> 789498.25 | C23: =A23-B23 -> -68418.898
A24: 691288.19 | B24: =98015.50529 +(1.202273376*Cleaned_Data!E211) +(33.98425653*Cleaned_Data!F211) +(2886.7347*Cleaned_Data!I211) +(11024.99051*Cleaned_Data!L211) +(-8375.710551*Cleaned_Data!O211) +(4929.586703*Cleaned_Data!P211) +(-17042.83335*Cleaned_Data!Q211) -> 759544.76 | C24: =A24-B24 -> -68256.573
A25: 630829.94 | B25: =98015.50529 +(1.202273376*Cleaned_Data!E75) +(33.98425653*Cleaned_Data!F75) +(2886.7347*Cleaned_Data!I75) +(11024.99051*Cleaned_Data!L75) +(-8375.710551*Cleaned_Data!O75) +(4929.586703*Cleaned_Data!P75) +(-17042.83335*Cleaned_Data!Q75) -> 699012.07 | C25: =A25-B25 -> -68182.134
A26: 441275.42 | B26: =98015.50529 +(1.202273376*Cleaned_Data!E125) +(33.98425653*Cleaned_Data!F125) +(2886.7347*Cleaned_Data!I125) +(11024.99051*Cleaned_Data!L125) +(-8375.710551*Cleaned_Data!O125) +(4929.586703*Cleaned_Data!P125) +(-17042.83335*Cleaned_Data!Q125) -> 508165.91 | C26: =A26-B26 -> -66890.494
A27: 651164.18 | B27: =98015.50529 +(1.202273376*Cleaned_Data!E309) +(33.98425653*Cleaned_Data!F309) +(2886.7347*Cleaned_Data!I309) +(11024.99051*Cleaned_Data!L309) +(-8375.710551*Cleaned_Data!O309) +(4929.586703*Cleaned_Data!P309) +(-17042.83335*Cleaned_Data!Q309) -> 717743.37 | C27: =A27-B27 -> -66579.189
A28: 660633.99 | B28: =98015.50529 +(1.202273376*Cleaned_Data!E270) +(33.98425653*Cleaned_Data!F270) +(2886.7347*Cleaned_Data!I270) +(11024.99051*Cleaned_Data!L270) +(-8375.710551*Cleaned_Data!O270) +(4929.586703*Cleaned_Data!P270) +(-17042.83335*Cleaned_Data!Q270) -> 726869.33 | C28: =A28-B28 -> -66235.342
A29: 675917.63 | B29: =98015.50529 +(1.202273376*Cleaned_Data!E209) +(33.98425653*Cleaned_Data!F209) +(2886.7347*Cleaned_Data!I209) +(11024.99051*Cleaned_Data!L209) +(-8375.710551*Cleaned_Data!O209) +(4929.586703*Cleaned_Data!P209) +(-17042.83335*Cleaned_Data!Q209) -> 741959.63 | C29: =A29-B29 -> -66042.003
A30: 799477.76 | B30: =98015.50529 +(1.202273376*Cleaned_Data!E35) +(33.98425653*Cleaned_Data!F35) +(2886.7347*Cleaned_Data!I35) +(11024.99051*Cleaned_Data!L35) +(-8375.710551*Cleaned_Data!O35) +(4929.586703*Cleaned_Data!P35) +(-17042.83335*Cleaned_Data!Q35) -> 863504.07 | C30: =A30-B30 -> -64026.31
A31: 725235.28 | B31: =98015.50529 +(1.202273376*Cleaned_Data!E132) +(33.98425653*Cleaned_Data!F132) +(2886.7347*Cleaned_Data!I132) +(11024.99051*Cleaned_Data!L132) +(-8375.710551*Cleaned_Data!O132) +(4929.586703*Cleaned_Data!P132) +(-17042.83335*Cleaned_Data!Q132) -> 789253.5 | C31: =A31-B31 -> -64018.225
A32: 634436 | B32: =98015.50529 +(1.202273376*Cleaned_Data!E3) +(33.98425653*Cleaned_Data!F3) +(2886.7347*Cleaned_Data!I3) +(11024.99051*Cleaned_Data!L3) +(-8375.710551*Cleaned_Data!O3) +(4929.586703*Cleaned_Data!P3) +(-17042.83335*Cleaned_Data!Q3) -> 696600.54 | C32: =A32-B32 -> -62164.544
A33: 593343 | B33: =98015.50529 +(1.202273376*Cleaned_Data!E273) +(33.98425653*Cleaned_Data!F273) +(2886.7347*Cleaned_Data!I273) +(11024.99051*Cleaned_Data!L273) +(-8375.710551*Cleaned_Data!O273) +(4929.586703*Cleaned_Data!P273) +(-17042.83335*Cleaned_Data!Q273) -> 653416.57 | C33: =A33-B33 -> -60073.575
A34: 650480.06 | B34: =98015.50529 +(1.202273376*Cleaned_Data!E162) +(33.98425653*Cleaned_Data!F162) +(2886.7347*Cleaned_Data!I162) +(11024.99051*Cleaned_Data!L162) +(-8375.710551*Cleaned_Data!O162) +(4929.586703*Cleaned_Data!P162) +(-17042.83335*Cleaned_Data!Q162) -> 710318.79 | C34: =A34-B34 -> -59838.731
A35: 620264.2 | B35: =98015.50529 +(1.202273376*Cleaned_Data!E318) +(33.98425653*Cleaned_Data!F318) +(2886.7347*Cleaned_Data!I318) +(11024.99051*Cleaned_Data!L318) +(-8375.710551*Cleaned_Data!O318) +(4929.586703*Cleaned_Data!P318) +(-17042.83335*Cleaned_Data!Q318) -> 676998.87 | C35: =A35-B35 -> -56734.667
A36: 726606.28 | B36: =98015.50529 +(1.202273376*Cleaned_Data!E15) +(33.98425653*Cleaned_Data!F15) +(2886.7347*Cleaned_Data!I15) +(11024.99051*Cleaned_Data!L15) +(-8375.710551*Cleaned_Data!O15) +(4929.586703*Cleaned_Data!P15) +(-17042.83335*Cleaned_Data!Q15) -> 782128.47 | C36: =A36-B36 -> -55522.192
A37: 400831.65 | B37: =98015.50529 +(1.202273376*Cleaned_Data!E135) +(33.98425653*Cleaned_Data!F135) +(2886.7347*Cleaned_Data!I135) +(11024.99051*Cleaned_Data!L135) +(-8375.710551*Cleaned_Data!O135) +(4929.586703*Cleaned_Data!P135) +(-17042.83335*Cleaned_Data!Q135) -> 455155.53 | C37: =A37-B37 -> -54323.878
A38: 527300.13 | B38: =98015.50529 +(1.202273376*Cleaned_Data!E134) +(33.98425653*Cleaned_Data!F134) +(2886.7347*Cleaned_Data!I134) +(11024.99051*Cleaned_Data!L134) +(-8375.710551*Cleaned_Data!O134) +(4929.586703*Cleaned_Data!P134) +(-17042.83335*Cleaned_Data!Q134) -> 579799.13 | C38: =A38-B38 -> -52498.996
A39: 536524.84 | B39: =98015.50529 +(1.202273376*Cleaned_Data!E311) +(33.98425653*Cleaned_Data!F311) +(2886.7347*Cleaned_Data!I311) +(11024.99051*Cleaned_Data!L311) +(-8375.710551*Cleaned_Data!O311) +(4929.586703*Cleaned_Data!P311) +(-17042.83335*Cleaned_Data!Q311) -> 588528.84 | C39: =A39-B39 -> -52004.003
A40: 509484.81 | B40: =98015.50529 +(1.202273376*Cleaned_Data!E122) +(33.98425653*Cleaned_Data!F122) +(2886.7347*Cleaned_Data!I122) +(11024.99051*Cleaned_Data!L122) +(-8375.710551*Cleaned_Data!O122) +(4929.586703*Cleaned_Data!P122) +(-17042.83335*Cleaned_Data!Q122) -> 561465.22 | C40: =A40-B40 -> -51980.412
A41: 643428.85 | B41: =98015.50529 +(1.202273376*Cleaned_Data!E194) +(33.98425653*Cleaned_Data!F194) +(2886.7347*Cleaned_Data!I194) +(11024.99051*Cleaned_Data!L194) +(-8375.710551*Cleaned_Data!O194) +(4929.586703*Cleaned_Data!P194) +(-17042.83335*Cleaned_Data!Q194) -> 695302.25 | C41: =A41-B41 -> -51873.4
...
